2023-03-15 10:31:44,447 django.security.csrf WARNING  Forbidden (Origin checking failed - http://localhost:8000 does not match any trusted origins.): /admin/login/
2023-03-15 10:32:15,047 django.security.csrf WARNING  Forbidden (Origin checking failed - http://localhost:8000 does not match any trusted origins.): /admin/login/
2023-03-15 10:37:55,492 django.security.csrf WARNING  Forbidden (Origin checking failed - http://localhost:8000 does not match any trusted origins.): /admin/login/
2023-03-15 10:39:04,289 django.request WARNING  Not Found: /
2023-03-15 10:39:19,890 django.request WARNING  Not Found: /
2023-03-15 10:39:26,943 django.request WARNING  Not Found: /
2023-03-15 10:39:29,428 django.request WARNING  Not Found: /
2023-03-15 10:39:30,208 django.request WARNING  Not Found: /
2023-03-15 10:41:13,881 django.security.csrf WARNING  Forbidden (Origin checking failed - http://127.0.0.1:8000 does not match any trusted origins.): /admin/login/
2023-03-15 10:47:13,960 django.request ERROR    Internal Server Error: /admin/login/
Traceback (most recent call last):
  File "/usr/local/lib/python3.11/site-packages/django/db/backends/base/base.py", line 282, in ensure_connection
    self.connect()
  File "/usr/local/lib/python3.11/site-packages/django/utils/asyncio.py", line 26, in inner
    return func(*args, **kwargs)
           ^^^^^^^^^^^^^^^^^^^^^
  File "/usr/local/lib/python3.11/site-packages/django/db/backends/base/base.py", line 263, in connect
    self.connection = self.get_new_connection(conn_params)
                      ^^^^^^^^^^^^^^^^^^^^^^^^^^^^^^^^^^^^
  File "/usr/local/lib/python3.11/site-packages/django/utils/asyncio.py", line 26, in inner
    return func(*args, **kwargs)
           ^^^^^^^^^^^^^^^^^^^^^
  File "/usr/local/lib/python3.11/site-packages/django/db/backends/postgresql/base.py", line 215, in get_new_connection
    connection = Database.connect(**conn_params)
                 ^^^^^^^^^^^^^^^^^^^^^^^^^^^^^^^
  File "/usr/local/lib/python3.11/site-packages/psycopg2/__init__.py", line 122, in connect
    conn = _connect(dsn, connection_factory=connection_factory, **kwasync)
           ^^^^^^^^^^^^^^^^^^^^^^^^^^^^^^^^^^^^^^^^^^^^^^^^^^^^^^^^^^^^^^^
psycopg2.OperationalError: could not translate host name "<host>" to address: Name or service not known


The above exception was the direct cause of the following exception:

Traceback (most recent call last):
  File "/usr/local/lib/python3.11/site-packages/django/core/handlers/exception.py", line 56, in inner
    response = get_response(request)
               ^^^^^^^^^^^^^^^^^^^^^
  File "/usr/local/lib/python3.11/site-packages/django/core/handlers/base.py", line 197, in _get_response
    response = wrapped_callback(request, *callback_args, **callback_kwargs)
               ^^^^^^^^^^^^^^^^^^^^^^^^^^^^^^^^^^^^^^^^^^^^^^^^^^^^^^^^^^^^
  File "/usr/local/lib/python3.11/site-packages/django/utils/decorators.py", line 46, in _wrapper
    return bound_method(*args, **kwargs)
           ^^^^^^^^^^^^^^^^^^^^^^^^^^^^^
  File "/usr/local/lib/python3.11/site-packages/django/views/decorators/cache.py", line 62, in _wrapped_view_func
    response = view_func(request, *args, **kwargs)
               ^^^^^^^^^^^^^^^^^^^^^^^^^^^^^^^^^^^
  File "/usr/local/lib/python3.11/site-packages/django/contrib/admin/sites.py", line 441, in login
    return LoginView.as_view(**defaults)(request)
           ^^^^^^^^^^^^^^^^^^^^^^^^^^^^^^^^^^^^^^
  File "/usr/local/lib/python3.11/site-packages/django/views/generic/base.py", line 103, in view
    return self.dispatch(request, *args, **kwargs)
           ^^^^^^^^^^^^^^^^^^^^^^^^^^^^^^^^^^^^^^^
  File "/usr/local/lib/python3.11/site-packages/django/utils/decorators.py", line 46, in _wrapper
    return bound_method(*args, **kwargs)
           ^^^^^^^^^^^^^^^^^^^^^^^^^^^^^
  File "/usr/local/lib/python3.11/site-packages/django/views/decorators/debug.py", line 92, in sensitive_post_parameters_wrapper
    return view(request, *args, **kwargs)
           ^^^^^^^^^^^^^^^^^^^^^^^^^^^^^^
  File "/usr/local/lib/python3.11/site-packages/django/utils/decorators.py", line 46, in _wrapper
    return bound_method(*args, **kwargs)
           ^^^^^^^^^^^^^^^^^^^^^^^^^^^^^
  File "/usr/local/lib/python3.11/site-packages/django/utils/decorators.py", line 134, in _wrapped_view
    response = view_func(request, *args, **kwargs)
               ^^^^^^^^^^^^^^^^^^^^^^^^^^^^^^^^^^^
  File "/usr/local/lib/python3.11/site-packages/django/utils/decorators.py", line 46, in _wrapper
    return bound_method(*args, **kwargs)
           ^^^^^^^^^^^^^^^^^^^^^^^^^^^^^
  File "/usr/local/lib/python3.11/site-packages/django/views/decorators/cache.py", line 62, in _wrapped_view_func
    response = view_func(request, *args, **kwargs)
               ^^^^^^^^^^^^^^^^^^^^^^^^^^^^^^^^^^^
  File "/usr/local/lib/python3.11/site-packages/django/contrib/auth/views.py", line 90, in dispatch
    return super().dispatch(request, *args, **kwargs)
           ^^^^^^^^^^^^^^^^^^^^^^^^^^^^^^^^^^^^^^^^^^
  File "/usr/local/lib/python3.11/site-packages/django/views/generic/base.py", line 142, in dispatch
    return handler(request, *args, **kwargs)
           ^^^^^^^^^^^^^^^^^^^^^^^^^^^^^^^^^
  File "/usr/local/lib/python3.11/site-packages/django/views/generic/edit.py", line 152, in post
    if form.is_valid():
       ^^^^^^^^^^^^^^^
  File "/usr/local/lib/python3.11/site-packages/django/forms/forms.py", line 205, in is_valid
    return self.is_bound and not self.errors
                                 ^^^^^^^^^^^
  File "/usr/local/lib/python3.11/site-packages/django/forms/forms.py", line 200, in errors
    self.full_clean()
  File "/usr/local/lib/python3.11/site-packages/django/forms/forms.py", line 438, in full_clean
    self._clean_form()
  File "/usr/local/lib/python3.11/site-packages/django/forms/forms.py", line 459, in _clean_form
    cleaned_data = self.clean()
                   ^^^^^^^^^^^^
  File "/usr/local/lib/python3.11/site-packages/django/contrib/auth/forms.py", line 217, in clean
    self.user_cache = authenticate(
                      ^^^^^^^^^^^^^
  File "/usr/local/lib/python3.11/site-packages/django/views/decorators/debug.py", line 42, in sensitive_variables_wrapper
    return func(*func_args, **func_kwargs)
           ^^^^^^^^^^^^^^^^^^^^^^^^^^^^^^^
  File "/usr/local/lib/python3.11/site-packages/django/contrib/auth/__init__.py", line 77, in authenticate
    user = backend.authenticate(request, **credentials)
           ^^^^^^^^^^^^^^^^^^^^^^^^^^^^^^^^^^^^^^^^^^^^
  File "/usr/local/lib/python3.11/site-packages/django/contrib/auth/backends.py", line 46, in authenticate
    user = UserModel._default_manager.get_by_natural_key(username)
           ^^^^^^^^^^^^^^^^^^^^^^^^^^^^^^^^^^^^^^^^^^^^^^^^^^^^^^^
  File "/usr/local/lib/python3.11/site-packages/django/contrib/auth/base_user.py", line 46, in get_by_natural_key
    return self.get(**{self.model.USERNAME_FIELD: username})
           ^^^^^^^^^^^^^^^^^^^^^^^^^^^^^^^^^^^^^^^^^^^^^^^^^
  File "/usr/local/lib/python3.11/site-packages/django/db/models/manager.py", line 85, in manager_method
    return getattr(self.get_queryset(), name)(*args, **kwargs)
           ^^^^^^^^^^^^^^^^^^^^^^^^^^^^^^^^^^^^^^^^^^^^^^^^^^^
  File "/usr/local/lib/python3.11/site-packages/django/db/models/query.py", line 646, in get
    num = len(clone)
          ^^^^^^^^^^
  File "/usr/local/lib/python3.11/site-packages/django/db/models/query.py", line 376, in __len__
    self._fetch_all()
  File "/usr/local/lib/python3.11/site-packages/django/db/models/query.py", line 1867, in _fetch_all
    self._result_cache = list(self._iterable_class(self))
                         ^^^^^^^^^^^^^^^^^^^^^^^^^^^^^^^^
  File "/usr/local/lib/python3.11/site-packages/django/db/models/query.py", line 87, in __iter__
    results = compiler.execute_sql(
              ^^^^^^^^^^^^^^^^^^^^^
  File "/usr/local/lib/python3.11/site-packages/django/db/models/sql/compiler.py", line 1396, in execute_sql
    cursor = self.connection.cursor()
             ^^^^^^^^^^^^^^^^^^^^^^^^
  File "/usr/local/lib/python3.11/site-packages/django/utils/asyncio.py", line 26, in inner
    return func(*args, **kwargs)
           ^^^^^^^^^^^^^^^^^^^^^
  File "/usr/local/lib/python3.11/site-packages/django/db/backends/base/base.py", line 323, in cursor
    return self._cursor()
           ^^^^^^^^^^^^^^
  File "/usr/local/lib/python3.11/site-packages/django/db/backends/base/base.py", line 299, in _cursor
    self.ensure_connection()
  File "/usr/local/lib/python3.11/site-packages/django/utils/asyncio.py", line 26, in inner
    return func(*args, **kwargs)
           ^^^^^^^^^^^^^^^^^^^^^
  File "/usr/local/lib/python3.11/site-packages/django/db/backends/base/base.py", line 281, in ensure_connection
    with self.wrap_database_errors:
  File "/usr/local/lib/python3.11/site-packages/django/db/utils.py", line 91, in __exit__
    raise dj_exc_value.with_traceback(traceback) from exc_value
  File "/usr/local/lib/python3.11/site-packages/django/db/backends/base/base.py", line 282, in ensure_connection
    self.connect()
  File "/usr/local/lib/python3.11/site-packages/django/utils/asyncio.py", line 26, in inner
    return func(*args, **kwargs)
           ^^^^^^^^^^^^^^^^^^^^^
  File "/usr/local/lib/python3.11/site-packages/django/db/backends/base/base.py", line 263, in connect
    self.connection = self.get_new_connection(conn_params)
                      ^^^^^^^^^^^^^^^^^^^^^^^^^^^^^^^^^^^^
  File "/usr/local/lib/python3.11/site-packages/django/utils/asyncio.py", line 26, in inner
    return func(*args, **kwargs)
           ^^^^^^^^^^^^^^^^^^^^^
  File "/usr/local/lib/python3.11/site-packages/django/db/backends/postgresql/base.py", line 215, in get_new_connection
    connection = Database.connect(**conn_params)
                 ^^^^^^^^^^^^^^^^^^^^^^^^^^^^^^^
  File "/usr/local/lib/python3.11/site-packages/psycopg2/__init__.py", line 122, in connect
    conn = _connect(dsn, connection_factory=connection_factory, **kwasync)
           ^^^^^^^^^^^^^^^^^^^^^^^^^^^^^^^^^^^^^^^^^^^^^^^^^^^^^^^^^^^^^^^
django.db.utils.OperationalError: could not translate host name "<host>" to address: Name or service not known

2023-03-15 11:00:43,859 django.request ERROR    Internal Server Error: /admin/login/
Traceback (most recent call last):
  File "/usr/local/lib/python3.11/site-packages/django/db/backends/base/base.py", line 282, in ensure_connection
    self.connect()
  File "/usr/local/lib/python3.11/site-packages/django/utils/asyncio.py", line 26, in inner
    return func(*args, **kwargs)
           ^^^^^^^^^^^^^^^^^^^^^
  File "/usr/local/lib/python3.11/site-packages/django/db/backends/base/base.py", line 263, in connect
    self.connection = self.get_new_connection(conn_params)
                      ^^^^^^^^^^^^^^^^^^^^^^^^^^^^^^^^^^^^
  File "/usr/local/lib/python3.11/site-packages/django/utils/asyncio.py", line 26, in inner
    return func(*args, **kwargs)
           ^^^^^^^^^^^^^^^^^^^^^
  File "/usr/local/lib/python3.11/site-packages/django/db/backends/postgresql/base.py", line 215, in get_new_connection
    connection = Database.connect(**conn_params)
                 ^^^^^^^^^^^^^^^^^^^^^^^^^^^^^^^
  File "/usr/local/lib/python3.11/site-packages/psycopg2/__init__.py", line 122, in connect
    conn = _connect(dsn, connection_factory=connection_factory, **kwasync)
           ^^^^^^^^^^^^^^^^^^^^^^^^^^^^^^^^^^^^^^^^^^^^^^^^^^^^^^^^^^^^^^^
psycopg2.OperationalError: could not translate host name "<host>" to address: Name or service not known


The above exception was the direct cause of the following exception:

Traceback (most recent call last):
  File "/usr/local/lib/python3.11/site-packages/django/core/handlers/exception.py", line 56, in inner
    response = get_response(request)
               ^^^^^^^^^^^^^^^^^^^^^
  File "/usr/local/lib/python3.11/site-packages/django/core/handlers/base.py", line 197, in _get_response
    response = wrapped_callback(request, *callback_args, **callback_kwargs)
               ^^^^^^^^^^^^^^^^^^^^^^^^^^^^^^^^^^^^^^^^^^^^^^^^^^^^^^^^^^^^
  File "/usr/local/lib/python3.11/site-packages/django/utils/decorators.py", line 46, in _wrapper
    return bound_method(*args, **kwargs)
           ^^^^^^^^^^^^^^^^^^^^^^^^^^^^^
  File "/usr/local/lib/python3.11/site-packages/django/views/decorators/cache.py", line 62, in _wrapped_view_func
    response = view_func(request, *args, **kwargs)
               ^^^^^^^^^^^^^^^^^^^^^^^^^^^^^^^^^^^
  File "/usr/local/lib/python3.11/site-packages/django/contrib/admin/sites.py", line 441, in login
    return LoginView.as_view(**defaults)(request)
           ^^^^^^^^^^^^^^^^^^^^^^^^^^^^^^^^^^^^^^
  File "/usr/local/lib/python3.11/site-packages/django/views/generic/base.py", line 103, in view
    return self.dispatch(request, *args, **kwargs)
           ^^^^^^^^^^^^^^^^^^^^^^^^^^^^^^^^^^^^^^^
  File "/usr/local/lib/python3.11/site-packages/django/utils/decorators.py", line 46, in _wrapper
    return bound_method(*args, **kwargs)
           ^^^^^^^^^^^^^^^^^^^^^^^^^^^^^
  File "/usr/local/lib/python3.11/site-packages/django/views/decorators/debug.py", line 92, in sensitive_post_parameters_wrapper
    return view(request, *args, **kwargs)
           ^^^^^^^^^^^^^^^^^^^^^^^^^^^^^^
  File "/usr/local/lib/python3.11/site-packages/django/utils/decorators.py", line 46, in _wrapper
    return bound_method(*args, **kwargs)
           ^^^^^^^^^^^^^^^^^^^^^^^^^^^^^
  File "/usr/local/lib/python3.11/site-packages/django/utils/decorators.py", line 134, in _wrapped_view
    response = view_func(request, *args, **kwargs)
               ^^^^^^^^^^^^^^^^^^^^^^^^^^^^^^^^^^^
  File "/usr/local/lib/python3.11/site-packages/django/utils/decorators.py", line 46, in _wrapper
    return bound_method(*args, **kwargs)
           ^^^^^^^^^^^^^^^^^^^^^^^^^^^^^
  File "/usr/local/lib/python3.11/site-packages/django/views/decorators/cache.py", line 62, in _wrapped_view_func
    response = view_func(request, *args, **kwargs)
               ^^^^^^^^^^^^^^^^^^^^^^^^^^^^^^^^^^^
  File "/usr/local/lib/python3.11/site-packages/django/contrib/auth/views.py", line 90, in dispatch
    return super().dispatch(request, *args, **kwargs)
           ^^^^^^^^^^^^^^^^^^^^^^^^^^^^^^^^^^^^^^^^^^
  File "/usr/local/lib/python3.11/site-packages/django/views/generic/base.py", line 142, in dispatch
    return handler(request, *args, **kwargs)
           ^^^^^^^^^^^^^^^^^^^^^^^^^^^^^^^^^
  File "/usr/local/lib/python3.11/site-packages/django/views/generic/edit.py", line 152, in post
    if form.is_valid():
       ^^^^^^^^^^^^^^^
  File "/usr/local/lib/python3.11/site-packages/django/forms/forms.py", line 205, in is_valid
    return self.is_bound and not self.errors
                                 ^^^^^^^^^^^
  File "/usr/local/lib/python3.11/site-packages/django/forms/forms.py", line 200, in errors
    self.full_clean()
  File "/usr/local/lib/python3.11/site-packages/django/forms/forms.py", line 438, in full_clean
    self._clean_form()
  File "/usr/local/lib/python3.11/site-packages/django/forms/forms.py", line 459, in _clean_form
    cleaned_data = self.clean()
                   ^^^^^^^^^^^^
  File "/usr/local/lib/python3.11/site-packages/django/contrib/auth/forms.py", line 217, in clean
    self.user_cache = authenticate(
                      ^^^^^^^^^^^^^
  File "/usr/local/lib/python3.11/site-packages/django/views/decorators/debug.py", line 42, in sensitive_variables_wrapper
    return func(*func_args, **func_kwargs)
           ^^^^^^^^^^^^^^^^^^^^^^^^^^^^^^^
  File "/usr/local/lib/python3.11/site-packages/django/contrib/auth/__init__.py", line 77, in authenticate
    user = backend.authenticate(request, **credentials)
           ^^^^^^^^^^^^^^^^^^^^^^^^^^^^^^^^^^^^^^^^^^^^
  File "/usr/local/lib/python3.11/site-packages/django/contrib/auth/backends.py", line 46, in authenticate
    user = UserModel._default_manager.get_by_natural_key(username)
           ^^^^^^^^^^^^^^^^^^^^^^^^^^^^^^^^^^^^^^^^^^^^^^^^^^^^^^^
  File "/usr/local/lib/python3.11/site-packages/django/contrib/auth/base_user.py", line 46, in get_by_natural_key
    return self.get(**{self.model.USERNAME_FIELD: username})
           ^^^^^^^^^^^^^^^^^^^^^^^^^^^^^^^^^^^^^^^^^^^^^^^^^
  File "/usr/local/lib/python3.11/site-packages/django/db/models/manager.py", line 85, in manager_method
    return getattr(self.get_queryset(), name)(*args, **kwargs)
           ^^^^^^^^^^^^^^^^^^^^^^^^^^^^^^^^^^^^^^^^^^^^^^^^^^^
  File "/usr/local/lib/python3.11/site-packages/django/db/models/query.py", line 646, in get
    num = len(clone)
          ^^^^^^^^^^
  File "/usr/local/lib/python3.11/site-packages/django/db/models/query.py", line 376, in __len__
    self._fetch_all()
  File "/usr/local/lib/python3.11/site-packages/django/db/models/query.py", line 1867, in _fetch_all
    self._result_cache = list(self._iterable_class(self))
                         ^^^^^^^^^^^^^^^^^^^^^^^^^^^^^^^^
  File "/usr/local/lib/python3.11/site-packages/django/db/models/query.py", line 87, in __iter__
    results = compiler.execute_sql(
              ^^^^^^^^^^^^^^^^^^^^^
  File "/usr/local/lib/python3.11/site-packages/django/db/models/sql/compiler.py", line 1396, in execute_sql
    cursor = self.connection.cursor()
             ^^^^^^^^^^^^^^^^^^^^^^^^
  File "/usr/local/lib/python3.11/site-packages/django/utils/asyncio.py", line 26, in inner
    return func(*args, **kwargs)
           ^^^^^^^^^^^^^^^^^^^^^
  File "/usr/local/lib/python3.11/site-packages/django/db/backends/base/base.py", line 323, in cursor
    return self._cursor()
           ^^^^^^^^^^^^^^
  File "/usr/local/lib/python3.11/site-packages/django/db/backends/base/base.py", line 299, in _cursor
    self.ensure_connection()
  File "/usr/local/lib/python3.11/site-packages/django/utils/asyncio.py", line 26, in inner
    return func(*args, **kwargs)
           ^^^^^^^^^^^^^^^^^^^^^
  File "/usr/local/lib/python3.11/site-packages/django/db/backends/base/base.py", line 281, in ensure_connection
    with self.wrap_database_errors:
  File "/usr/local/lib/python3.11/site-packages/django/db/utils.py", line 91, in __exit__
    raise dj_exc_value.with_traceback(traceback) from exc_value
  File "/usr/local/lib/python3.11/site-packages/django/db/backends/base/base.py", line 282, in ensure_connection
    self.connect()
  File "/usr/local/lib/python3.11/site-packages/django/utils/asyncio.py", line 26, in inner
    return func(*args, **kwargs)
           ^^^^^^^^^^^^^^^^^^^^^
  File "/usr/local/lib/python3.11/site-packages/django/db/backends/base/base.py", line 263, in connect
    self.connection = self.get_new_connection(conn_params)
                      ^^^^^^^^^^^^^^^^^^^^^^^^^^^^^^^^^^^^
  File "/usr/local/lib/python3.11/site-packages/django/utils/asyncio.py", line 26, in inner
    return func(*args, **kwargs)
           ^^^^^^^^^^^^^^^^^^^^^
  File "/usr/local/lib/python3.11/site-packages/django/db/backends/postgresql/base.py", line 215, in get_new_connection
    connection = Database.connect(**conn_params)
                 ^^^^^^^^^^^^^^^^^^^^^^^^^^^^^^^
  File "/usr/local/lib/python3.11/site-packages/psycopg2/__init__.py", line 122, in connect
    conn = _connect(dsn, connection_factory=connection_factory, **kwasync)
           ^^^^^^^^^^^^^^^^^^^^^^^^^^^^^^^^^^^^^^^^^^^^^^^^^^^^^^^^^^^^^^^
django.db.utils.OperationalError: could not translate host name "<host>" to address: Name or service not known

2023-03-15 14:53:29,288 django.request WARNING  Not Found: /
2023-03-15 14:54:53,007 django.request WARNING  Not Found: /
2023-03-15 14:55:34,057 django.request WARNING  Not Found: /
2023-03-15 14:55:34,901 django.request WARNING  Not Found: /
2023-03-15 15:32:34,204 django.request ERROR    Internal Server Error: /
Traceback (most recent call last):
  File "/usr/local/lib/python3.11/site-packages/django/core/handlers/exception.py", line 56, in inner
    response = get_response(request)
               ^^^^^^^^^^^^^^^^^^^^^
  File "/usr/local/lib/python3.11/site-packages/django/core/handlers/base.py", line 197, in _get_response
    response = wrapped_callback(request, *callback_args, **callback_kwargs)
               ^^^^^^^^^^^^^^^^^^^^^^^^^^^^^^^^^^^^^^^^^^^^^^^^^^^^^^^^^^^^
  File "/code/apps/home/views.py", line 7, in index
    return render(request, 'apps/home/detail.html', {})
           ^^^^^^^^^^^^^^^^^^^^^^^^^^^^^^^^^^^^^^^^^^^^
  File "/usr/local/lib/python3.11/site-packages/django/shortcuts.py", line 24, in render
    content = loader.render_to_string(template_name, context, request, using=using)
              ^^^^^^^^^^^^^^^^^^^^^^^^^^^^^^^^^^^^^^^^^^^^^^^^^^^^^^^^^^^^^^^^^^^^^
  File "/usr/local/lib/python3.11/site-packages/django/template/loader.py", line 61, in render_to_string
    template = get_template(template_name, using=using)
               ^^^^^^^^^^^^^^^^^^^^^^^^^^^^^^^^^^^^^^^^
  File "/usr/local/lib/python3.11/site-packages/django/template/loader.py", line 19, in get_template
    raise TemplateDoesNotExist(template_name, chain=chain)
django.template.exceptions.TemplateDoesNotExist: apps/home/detail.html
2023-03-16 14:53:05,868 django.request WARNING  Not Found: /uploads/cards/Invitation-card-6.jpg
2023-03-16 14:53:06,634 django.request WARNING  Not Found: /uploads/cards/Invitation-card-6.jpg
2023-03-16 14:53:06,810 django.request WARNING  Not Found: /uploads/cards/Invitation-card-6.jpg
2023-03-16 14:53:07,026 django.request WARNING  Not Found: /uploads/cards/Invitation-card-6.jpg
2023-03-16 14:53:07,159 django.request WARNING  Not Found: /uploads/cards/Invitation-card-6.jpg
2023-03-16 14:53:07,331 django.request WARNING  Not Found: /uploads/cards/Invitation-card-6.jpg
2023-03-16 14:53:07,498 django.request WARNING  Not Found: /uploads/cards/Invitation-card-6.jpg
2023-03-16 14:53:07,662 django.request WARNING  Not Found: /uploads/cards/Invitation-card-6.jpg
2023-03-16 14:53:07,832 django.request WARNING  Not Found: /uploads/cards/Invitation-card-6.jpg
2023-03-16 14:53:08,007 django.request WARNING  Not Found: /uploads/cards/Invitation-card-6.jpg
2023-03-16 14:53:08,148 django.request WARNING  Not Found: /uploads/cards/Invitation-card-6.jpg
2023-03-16 14:53:08,333 django.request WARNING  Not Found: /uploads/cards/Invitation-card-6.jpg
2023-03-17 09:12:14,206 django.request WARNING  Not Found: /invitation/8a703aaf-c45c-408f-bfbe-7b23d28e525c/no
2024-07-16 11:08:33,725 django.request ERROR    Internal Server Error: /
Traceback (most recent call last):
  File "/usr/local/lib/python3.12/site-packages/django/db/backends/base/base.py", line 289, in ensure_connection
    self.connect()
  File "/usr/local/lib/python3.12/site-packages/django/utils/asyncio.py", line 26, in inner
    return func(*args, **kwargs)
           ^^^^^^^^^^^^^^^^^^^^^
  File "/usr/local/lib/python3.12/site-packages/django/db/backends/base/base.py", line 270, in connect
    self.connection = self.get_new_connection(conn_params)
                      ^^^^^^^^^^^^^^^^^^^^^^^^^^^^^^^^^^^^
  File "/usr/local/lib/python3.12/site-packages/django/utils/asyncio.py", line 26, in inner
    return func(*args, **kwargs)
           ^^^^^^^^^^^^^^^^^^^^^
  File "/usr/local/lib/python3.12/site-packages/django/db/backends/postgresql/base.py", line 275, in get_new_connection
    connection = self.Database.connect(**conn_params)
                 ^^^^^^^^^^^^^^^^^^^^^^^^^^^^^^^^^^^^
  File "/usr/local/lib/python3.12/site-packages/psycopg2/__init__.py", line 122, in connect
    conn = _connect(dsn, connection_factory=connection_factory, **kwasync)
           ^^^^^^^^^^^^^^^^^^^^^^^^^^^^^^^^^^^^^^^^^^^^^^^^^^^^^^^^^^^^^^^
psycopg2.OperationalError: could not translate host name "<host>" to address: Name or service not known


The above exception was the direct cause of the following exception:

Traceback (most recent call last):
  File "/usr/local/lib/python3.12/site-packages/django/core/handlers/exception.py", line 55, in inner
    response = get_response(request)
               ^^^^^^^^^^^^^^^^^^^^^
  File "/usr/local/lib/python3.12/site-packages/django/core/handlers/base.py", line 197, in _get_response
    response = wrapped_callback(request, *callback_args, **callback_kwargs)
               ^^^^^^^^^^^^^^^^^^^^^^^^^^^^^^^^^^^^^^^^^^^^^^^^^^^^^^^^^^^^
  File "/home/user/app/apps/home/views.py", line 13, in index
    page_obj = paginator.get_page(page_number)
               ^^^^^^^^^^^^^^^^^^^^^^^^^^^^^^^
  File "/usr/local/lib/python3.12/site-packages/django/core/paginator.py", line 68, in get_page
    return self.page(number)
           ^^^^^^^^^^^^^^^^^
  File "/usr/local/lib/python3.12/site-packages/django/core/paginator.py", line 72, in page
    number = self.validate_number(number)
             ^^^^^^^^^^^^^^^^^^^^^^^^^^^^
  File "/usr/local/lib/python3.12/site-packages/django/core/paginator.py", line 53, in validate_number
    if number > self.num_pages:
                ^^^^^^^^^^^^^^
  File "/usr/local/lib/python3.12/site-packages/django/utils/functional.py", line 57, in __get__
    res = instance.__dict__[self.name] = self.func(instance)
                                         ^^^^^^^^^^^^^^^^^^^
  File "/usr/local/lib/python3.12/site-packages/django/core/paginator.py", line 99, in num_pages
    if self.count == 0 and not self.allow_empty_first_page:
       ^^^^^^^^^^
  File "/usr/local/lib/python3.12/site-packages/django/utils/functional.py", line 57, in __get__
    res = instance.__dict__[self.name] = self.func(instance)
                                         ^^^^^^^^^^^^^^^^^^^
  File "/usr/local/lib/python3.12/site-packages/django/core/paginator.py", line 93, in count
    return c()
           ^^^
  File "/usr/local/lib/python3.12/site-packages/django/db/models/query.py", line 608, in count
    return self.query.get_count(using=self.db)
           ^^^^^^^^^^^^^^^^^^^^^^^^^^^^^^^^^^^
  File "/usr/local/lib/python3.12/site-packages/django/db/models/sql/query.py", line 568, in get_count
    return obj.get_aggregation(using, {"__count": Count("*")})["__count"]
           ^^^^^^^^^^^^^^^^^^^^^^^^^^^^^^^^^^^^^^^^^^^^^^^^^^^
  File "/usr/local/lib/python3.12/site-packages/django/db/models/sql/query.py", line 554, in get_aggregation
    result = compiler.execute_sql(SINGLE)
             ^^^^^^^^^^^^^^^^^^^^^^^^^^^^
  File "/usr/local/lib/python3.12/site-packages/django/db/models/sql/compiler.py", line 1560, in execute_sql
    cursor = self.connection.cursor()
             ^^^^^^^^^^^^^^^^^^^^^^^^
  File "/usr/local/lib/python3.12/site-packages/django/utils/asyncio.py", line 26, in inner
    return func(*args, **kwargs)
           ^^^^^^^^^^^^^^^^^^^^^
  File "/usr/local/lib/python3.12/site-packages/django/db/backends/base/base.py", line 330, in cursor
    return self._cursor()
           ^^^^^^^^^^^^^^
  File "/usr/local/lib/python3.12/site-packages/django/db/backends/base/base.py", line 306, in _cursor
    self.ensure_connection()
  File "/usr/local/lib/python3.12/site-packages/django/utils/asyncio.py", line 26, in inner
    return func(*args, **kwargs)
           ^^^^^^^^^^^^^^^^^^^^^
  File "/usr/local/lib/python3.12/site-packages/django/db/backends/base/base.py", line 288, in ensure_connection
    with self.wrap_database_errors:
  File "/usr/local/lib/python3.12/site-packages/django/db/utils.py", line 91, in __exit__
    raise dj_exc_value.with_traceback(traceback) from exc_value
  File "/usr/local/lib/python3.12/site-packages/django/db/backends/base/base.py", line 289, in ensure_connection
    self.connect()
  File "/usr/local/lib/python3.12/site-packages/django/utils/asyncio.py", line 26, in inner
    return func(*args, **kwargs)
           ^^^^^^^^^^^^^^^^^^^^^
  File "/usr/local/lib/python3.12/site-packages/django/db/backends/base/base.py", line 270, in connect
    self.connection = self.get_new_connection(conn_params)
                      ^^^^^^^^^^^^^^^^^^^^^^^^^^^^^^^^^^^^
  File "/usr/local/lib/python3.12/site-packages/django/utils/asyncio.py", line 26, in inner
    return func(*args, **kwargs)
           ^^^^^^^^^^^^^^^^^^^^^
  File "/usr/local/lib/python3.12/site-packages/django/db/backends/postgresql/base.py", line 275, in get_new_connection
    connection = self.Database.connect(**conn_params)
                 ^^^^^^^^^^^^^^^^^^^^^^^^^^^^^^^^^^^^
  File "/usr/local/lib/python3.12/site-packages/psycopg2/__init__.py", line 122, in connect
    conn = _connect(dsn, connection_factory=connection_factory, **kwasync)
           ^^^^^^^^^^^^^^^^^^^^^^^^^^^^^^^^^^^^^^^^^^^^^^^^^^^^^^^^^^^^^^^
django.db.utils.OperationalError: could not translate host name "<host>" to address: Name or service not known

2024-07-17 14:40:07,771 django.utils.autoreload INFO     Watching for file changes with StatReloader
2024-07-17 14:40:17,787 django.server INFO     "GET / HTTP/1.1" 200 10963
2024-07-17 14:40:17,807 django.server INFO     "GET /media/CACHE/images/images/bridge/45a6860e597dd5bd1b40d4bce87c54b6.jpg HTTP/1.1" 304 0
2024-07-17 14:40:17,808 django.server INFO     "GET /media/CACHE/images/images/benches/420026aee11b5aff872e37bfd47ee7fb.jpg HTTP/1.1" 304 0
2024-07-17 14:40:17,814 django.server INFO     "GET /media/CACHE/images/images/traffic/9ff60b1de772fdbdf52cc1b7664b49cd.jpg HTTP/1.1" 304 0
2024-07-17 14:40:17,815 django.server INFO     "GET /media/CACHE/images/images/coast/a327f0182f0e324da7fc1edabcea2210.jpg HTTP/1.1" 304 0
2024-07-17 14:40:17,818 django.server INFO     "GET /media/CACHE/images/images/sky/ce5908530ee5a61edb6bfcf88ebf953a.jpg HTTP/1.1" 304 0
2024-07-17 14:40:17,819 django.server INFO     "GET /media/CACHE/images/images/park/0a44378895515d97cc72e57ef3e72eb6.jpg HTTP/1.1" 304 0
2024-07-17 14:40:17,819 django.server INFO     "GET /media/CACHE/images/images/rails/5c6cfc5c37eae9d8e931ced8b839797f.jpg HTTP/1.1" 304 0
2024-07-17 14:40:17,821 django.server INFO     "GET /media/CACHE/images/images/rocks/d96a2abd8bb801b315dda710b9f509c1.jpg HTTP/1.1" 304 0
2024-07-17 14:40:17,822 django.server INFO     "GET /media/CACHE/images/images/tunnel/0cbcd2bcbb1a4e9edbd2157f6f4c6ebf.jpg HTTP/1.1" 304 0
2024-07-17 14:40:18,628 django.server INFO     "GET / HTTP/1.1" 200 10963
2024-07-17 14:40:18,829 django.server INFO     "GET / HTTP/1.1" 200 10963
2024-07-17 14:40:18,984 django.server INFO     "GET / HTTP/1.1" 200 10963
2024-07-17 14:40:19,164 django.server INFO     "GET / HTTP/1.1" 200 10963
2024-07-17 14:40:19,330 django.server INFO     "GET / HTTP/1.1" 200 10963
2024-07-17 14:40:19,504 django.server INFO     "GET / HTTP/1.1" 200 10963
2024-07-17 14:40:19,671 django.server INFO     "GET / HTTP/1.1" 200 10963
2024-07-17 14:40:19,838 django.server INFO     "GET / HTTP/1.1" 200 10963
2024-07-17 14:40:20,023 django.server INFO     "GET / HTTP/1.1" 200 10963
2024-07-17 14:40:20,165 django.server INFO     "GET / HTTP/1.1" 200 10963
2024-07-17 14:40:20,333 django.server INFO     "GET / HTTP/1.1" 200 10963
2024-07-17 14:40:20,504 django.server INFO     "GET / HTTP/1.1" 200 10963
2024-07-17 14:40:20,668 django.server INFO     "GET / HTTP/1.1" 200 10963
2024-07-17 14:40:20,850 django.server INFO     "GET / HTTP/1.1" 200 10963
2024-07-17 14:40:31,300 django.server INFO     "GET /admin/ HTTP/1.1" 200 11285
2024-07-17 14:40:31,729 django.server INFO     "GET /static/admin/img/icon-deletelink.svg HTTP/1.1" 304 0
2024-07-17 14:40:34,542 django.server INFO     "GET /admin/invitation/invitation/ HTTP/1.1" 200 9922
2024-07-17 14:40:34,561 django.server INFO     "GET /static/admin/js/core.js HTTP/1.1" 304 0
2024-07-17 14:40:34,562 django.server INFO     "GET /static/admin/js/jquery.init.js HTTP/1.1" 304 0
2024-07-17 14:40:34,562 django.server INFO     "GET /static/admin/css/changelists.css HTTP/1.1" 304 0
2024-07-17 14:40:34,563 django.server INFO     "GET /static/admin/js/vendor/jquery/jquery.js HTTP/1.1" 304 0
2024-07-17 14:40:34,563 django.server INFO     "GET /static/admin/js/admin/RelatedObjectLookups.js HTTP/1.1" 304 0
2024-07-17 14:40:34,566 django.server INFO     "GET /static/admin/js/actions.js HTTP/1.1" 304 0
2024-07-17 14:40:34,567 django.server INFO     "GET /static/admin/js/urlify.js HTTP/1.1" 304 0
2024-07-17 14:40:34,568 django.server INFO     "GET /static/admin/js/prepopulate.js HTTP/1.1" 304 0
2024-07-17 14:40:34,569 django.server INFO     "GET /static/admin/js/vendor/xregexp/xregexp.js HTTP/1.1" 304 0
2024-07-17 14:40:34,570 django.server INFO     "GET /admin/jsi18n/ HTTP/1.1" 200 3343
2024-07-17 14:40:34,573 django.server INFO     "GET /static/admin/js/filters.js HTTP/1.1" 304 0
2024-07-17 14:40:34,583 django.server INFO     "GET /static/admin/img/tooltag-add.svg HTTP/1.1" 304 0
2024-07-17 14:40:37,458 django.server INFO     "GET /admin/invitation/invitation/8a703aaf-c45c-408f-bfbe-7b23d28e525c/change/ HTTP/1.1" 200 14901
2024-07-17 14:40:37,467 django.server INFO     "GET /static/admin/css/forms.css HTTP/1.1" 304 0
2024-07-17 14:40:37,468 django.server INFO     "GET /static/admin/js/prepopulate_init.js HTTP/1.1" 304 0
2024-07-17 14:40:37,470 django.server INFO     "GET /static/admin/css/widgets.css HTTP/1.1" 304 0
2024-07-17 14:40:37,471 django.server INFO     "GET /static/admin/js/change_form.js HTTP/1.1" 304 0
2024-07-17 14:40:37,473 django.server INFO     "GET /admin/jsi18n/ HTTP/1.1" 200 3343
2024-07-17 14:40:39,404 django.server INFO     "GET /admin/home/gallery/ HTTP/1.1" 200 8569
2024-07-17 14:40:39,421 django.server INFO     "GET /admin/jsi18n/ HTTP/1.1" 200 3343
2024-07-17 14:40:40,831 django.server INFO     "GET /admin/home/photo/ HTTP/1.1" 200 12356
2024-07-17 14:40:40,841 django.server INFO     "GET /admin/jsi18n/ HTTP/1.1" 200 3343
2024-07-17 14:40:42,188 django.server INFO     "GET /admin/home/photo/f680c3cd-8874-442a-8e02-cf6de41a43c5/change/ HTTP/1.1" 200 9966
2024-07-17 14:40:42,203 django.server INFO     "GET /admin/jsi18n/ HTTP/1.1" 200 3343
2024-07-17 14:40:47,513 django.server INFO     "GET /admin/ HTTP/1.1" 200 11285
